Workbook

Sheet Technomic Top 500 Chains
A1: Chain Name | B1: Ignite ID | C1: Segment | D1: Subsegment | E1: Menu Type | F1: Rank | G1: 2024 U.S. Sales ($000) | H1: 2024 Market share (%) | I1: 2024 U.S. Units | J1: 2024 AUV | K1: 2024 YoY units % | L1: 5-Year Sales CAGR | M1: 5-year market share change | N1: 5-Year AUV CAGR | O1: 5-Year Unit CAGR | P1: 2023 U.S. Sales ($000) | Q1: 2023 Market share (%) | R1: Market share y/y | S1: 2023 YoY Sales % | T1: 2023 U.S. Units | U1: 2023 AUV | V1: 2023 YoY Units % | W1: 4-Year Sales CAGR | X1: 4-year market share change | Y1: 4-Year AUV CAGR | Z1: 4-Year Unit CAGR | AA1: 2022 U.S. Sales ($000) | AB1: 2022 Market share (%) | AC1: 2022 U.S. Units | AD1: 2022 AUV | AE1: 2021 U.S. Sales ($000) | AF1: 2021 Market share (%) | AG1: 2021 U.S. Units | AH1: 2021 AUV | AI1: 2020 U.S. Sales ($000) | AJ1: 2020 Market share (%) | AK1: 2020 U.S. Units | AL1: 2020 AUV | AM1: 2019 U.S. Sales ($000) | AN1: 2019 Market share (%) | AO1: 2019 U.S. Units | AP1: 2019 AUV
A2: McDonald's | B2: 823 | C2: LSR | D2: QSR | E2: Burger | F2: 1 | H2: =Table1[[#This Row],[2024 U.S. Sales ($000)]]/SUMIF($E:$E, E2, $G:$G) -> #DIV/0! | I2: =VLOOKUP(Table1[[#This Row],[Chain Name]],[1]Sheet1!A$3:G$26,7,0) -> #N/A | J2: =Table1[[#This Row],[2024 U.S. Sales ($000)]]/Table1[[#This Row],[2024 U.S. Units]] -> #N/A | K2: =Table1[[#This Row],[2024 U.S. Units]]/Table1[[#This Row],[2023 U.S. Units]]-1 -> #N/A | L2: =_xlfn.RRI(5,Table1[[#This Row],[2019 U.S. Sales ($000)]],Table1[[#This Row],[2024 U.S. Sales ($000)]]) -> -1 | M2: =(Table1[[#This Row],[2024 Market share (%)]]-Table1[[#This Row],[2019 Market share (%)]])*10000 -> #DIV/0! | P2: 53134100 | Q2: =Table1[[#This Row],[2023 U.S. Sales ($000)]]/SUMIF($E:$E, E2, $P:$P) -> 0.48531801 | R2: =(Table1[[#This Row],[2023 Market share (%)]]-Table1[[#This Row],[2022 Market share (%)]])*10000 -> 83.296125 | S2: 0.09028362 | T2: 13457 | U2: =P2/T2 -> 3948.4358 | V2: 0.00096697411 | W2: =_xlfn.RRI(4,AM2,P2) -> 0.070813568 | X2: =(Table1[[#This Row],[2023 Market share (%)]]-Table1[[#This Row],[2019 Market share (%)]])*10000 -> 181.64582 | Y2: =_xlfn.RRI(4,AP2,U2) -> 0.078469542 | Z2: =_xlfn.RRI(4,AO2,T2) -> -0.0070989241 | AA2: 48734200 | AB2: =Table1[[#This Row],[2022 U.S. Sales ($000)]]/SUMIF($E:$E, E2, $AA:$AA) -> 0.47698839 | AC2: 13444 | AD2: =AA2/AC2 -> 3624.9777 | AE2: 45960500 | AF2: =Table1[[#This Row],[2021 U.S. Sales ($000)]]/SUMIF($E:$E, E2, $AE:$AE) -> 0.47239191 | AG2: 13438 | AH2: =AE2/AG2 -> 3420.189 | AI2: 40517000 | AJ2: =Table1[[#This Row],[2020 U.S. Sales ($000)]]/SUMIF($E:$E, E2, $AI:$AI) -> 0.46366954 | AK2: 13682 | AL2: =AI2/AK2 -> 2961.3361 | AM2: 40412700 | AN2: =Table1[[#This Row],[2019 U.S. Sales ($000)]]/SUMIF($E:$E, E2, $AM:$AM) -> 0.46715342 | AO2: 13846 | AP2: =AM2/AO2 -> 2918.7274
A3: Dutch Bros Coffee | B3: 5876 | C3: LSR | D3: QSR | E3: Coffee Cafe | F3: 48 | G3: 1819000 | H3: =Table1[[#This Row],[2024 U.S. Sales ($000)]]/SUMIF($E:$E, E3, $G:$G) -> 0.035997693 | I3: 982 | J3: =Table1[[#This Row],[2024 U.S. Sales ($000)]]/Table1[[#This Row],[2024 U.S. Units]] -> 1852.3422 | K3: =Table1[[#This Row],[2024 U.S. Units]]/Table1[[#This Row],[2023 U.S. Units]]-1 -> 0.18170878 | L3: =_xlfn.RRI(5,Table1[[#This Row],[2019 U.S. Sales ($000)]],Table1[[#This Row],[2024 U.S. Sales ($000)]]) -> 0.26721804 | M3: =(Table1[[#This Row],[2024 Market share (%)]]-Table1[[#This Row],[2019 Market share (%)]])*10000 -> 200.87109 | P3: 1444433 | Q3: =Table1[[#This Row],[2023 U.S. Sales ($000)]]/SUMIF($E:$E, E3, $P:$P) -> 0.029464035 | R3: =(Table1[[#This Row],[2023 Market share (%)]]-Table1[[#This Row],[2022 Market share (%)]])*10000 -> 30.288686 | S3: 0.24179449 | T3: 831 | U3: =P3/T3 -> 1738.1865 | V3: 0.23845007 | W3: =_xlfn.RRI(4,AM3,P3) -> 0.26920086 | X3: =(Table1[[#This Row],[2023 Market share (%)]]-Table1[[#This Row],[2019 Market share (%)]])*10000 -> 135.53451 | Y3: =_xlfn.RRI(4,AP3,U3) -> 0.03676549 | Z3: =_xlfn.RRI(4,AO3,T3) -> 0.22419281 | AA3: 1163182 | AB3: =Table1[[#This Row],[2022 U.S. Sales ($000)]]/SUMIF($E:$E, E3, $AA:$AA) -> 0.026435166 | AC3: 671 | AD3: =AA3/AC3 -> 1733.5052 | AE3: 913822 | AF3: =Table1[[#This Row],[2021 U.S. Sales ($000)]]/SUMIF($E:$E, E3, $AE:$AE) -> 0.023545991 | AG3: 538 | AH3: =AE3/AG3 -> 1698.5539 | AI3: 687238 | AJ3: =Table1[[#This Row],[2020 U.S. Sales ($000)]]/SUMIF($E:$E, E3, $AI:$AI) -> 0.022162859 | AK3: 441 | AL3: =AI3/AK3 -> 1558.3628 | AM3: 556642 | AN3: =Table1[[#This Row],[2019 U.S. Sales ($000)]]/SUMIF($E:$E, E3, $AM:$AM) -> 0.015910584 | AO3: 370 | AP3: =AM3/AO3 -> 1504.4378
A4: Chick-fil-A | B4: 799 | C4: LSR | D4: QSR | E4: Chicken | F4: 3 | H4: =Table1[[#This Row],[2024 U.S. Sales ($000)]]/SUMIF($E:$E, E4, $G:$G) -> #DIV/0! | I4: =VLOOKUP(Table1[[#This Row],[Chain Name]],[1]Sheet1!A$3:G$26,7,0) -> #N/A | J4: =Table1[[#This Row],[2024 U.S. Sales ($000)]]/Table1[[#This Row],[2024 U.S. Units]] -> #N/A | K4: =Table1[[#This Row],[2024 U.S. Units]]/Table1[[#This Row],[2023 U.S. Units]]-1 -> #N/A | L4: =_xlfn.RRI(5,Table1[[#This Row],[2019 U.S. Sales ($000)]],Table1[[#This Row],[2024 U.S. Sales ($000)]]) -> -1 | M4: =(Table1[[#This Row],[2024 Market share (%)]]-Table1[[#This Row],[2019 Market share (%)]])*10000 -> #DIV/0! | P4: 21585752 | Q4: =Table1[[#This Row],[2023 U.S. Sales ($000)]]/SUMIF($E:$E, E4, $P:$P) -> 0.44068099 | R4: =(Table1[[#This Row],[2023 Market share (%)]]-Table1[[#This Row],[2022 Market share (%)]])*10000 -> 94.810629 | S4: 0.14732244 | T4: 2964 | U4: =P4/T4 -> 7282.6424 | V4: 0.056307912 | W4: =_xlfn.RRI(4,AM4,P4) -> 0.15429004 | X4: =(Table1[[#This Row],[2023 Market share (%)]]-Table1[[#This Row],[2019 Market share (%)]])*10000 -> 446.09137 | Y4: =_xlfn.RRI(4,AP4,U4) -> 0.10541656 | Z4: =_xlfn.RRI(4,AO4,T4) -> 0.044212722 | AA4: 18814024 | AB4: =Table1[[#This Row],[2022 U.S. Sales ($000)]]/SUMIF($E:$E, E4, $AA:$AA) -> 0.43119993 | AC4: 2806 | AD4: =AA4/AC4 -> 6704.9266 | AE4: 16673679 | AF4: =Table1[[#This Row],[2021 U.S. Sales ($000)]]/SUMIF($E:$E, E4, $AE:$AE) -> 0.4241062 | AG4: 2704 | AH4: =AE4/AG4 -> 6166.3014 | AI4: 13703568 | AJ4: =Table1[[#This Row],[2020 U.S. Sales ($000)]]/SUMIF($E:$E, E4, $AI:$AI) -> 0.40519938 | AK4: 2598 | AL4: =AI4/AK4 -> 5274.6605 | AM4: 12159267 | AN4: =Table1[[#This Row],[2019 U.S. Sales ($000)]]/SUMIF($E:$E, E4, $AM:$AM) -> 0.39607186 | AO4: 2493 | AP4: =AM4/AO4 -> 4877.3634
A5: Taco Bell | B5: 326 | C5: LSR | D5: QSR | E5: Mexican | F5: 4 | H5: =Table1[[#This Row],[2024 U.S. Sales ($000)]]/SUMIF($E:$E, E5, $G:$G) -> #DIV/0! | I5: =VLOOKUP(Table1[[#This Row],[Chain Name]],[1]Sheet1!A$3:G$26,7,0) -> #N/A | J5: =Table1[[#This Row],[2024 U.S. Sales ($000)]]/Table1[[#This Row],[2024 U.S. Units]] -> #N/A | K5: =Table1[[#This Row],[2024 U.S. Units]]/Table1[[#This Row],[2023 U.S. Units]]-1 -> #N/A | L5: =_xlfn.RRI(5,Table1[[#This Row],[2019 U.S. Sales ($000)]],Table1[[#This Row],[2024 U.S. Sales ($000)]]) -> -1 | M5: =(Table1[[#This Row],[2024 Market share (%)]]-Table1[[#This Row],[2019 Market share (%)]])*10000 -> #DIV/0! | P5: 14980000 | Q5: =Table1[[#This Row],[2023 U.S. Sales ($000)]]/SUMIF($E:$E, E5, $P:$P) -> 0.45272056 | R5: =(Table1[[#This Row],[2023 Market share (%)]]-Table1[[#This Row],[2022 Market share (%)]])*10000 -> -45.490474 | S5: 0.081588448 | T5: 7405 | U5: =P5/T5 -> 2022.9575 | V5: 0.028757988 | W5: =_xlfn.RRI(4,AM5,P5) -> 0.073187539 | X5: =(Table1[[#This Row],[2023 Market share (%)]]-Table1[[#This Row],[2019 Market share (%)]])*10000 -> -131.08469 | Y5: =_xlfn.RRI(4,AP5,U5) -> 0.049246077 | Z5: =_xlfn.RRI(4,AO5,T5) -> 0.022817776 | AA5: 13850000 | AB5: =Table1[[#This Row],[2022 U.S. Sales ($000)]]/SUMIF($E:$E, E5, $AA:$AA) -> 0.45726961 | AC5: 7198 | AD5: =AA5/AC5 -> 1924.1456 | AE5: 12615000 | AF5: =Table1[[#This Row],[2021 U.S. Sales ($000)]]/SUMIF($E:$E, E5, $AE:$AE) -> 0.46024598 | AG5: 7002 | AH5: =AE5/AG5 -> 1801.6281 | AI5: 11294000 | AJ5: =Table1[[#This Row],[2020 U.S. Sales ($000)]]/SUMIF($E:$E, E5, $AI:$AI) -> 0.47913516 | AK5: 6799 | AL5: =AI5/AK5 -> 1661.1266 | AM5: 11293000 | AN5: =Table1[[#This Row],[2019 U.S. Sales ($000)]]/SUMIF($E:$E, E5, $AM:$AM) -> 0.46582903 | AO5: 6766 | AP5: =AM5/AO5 -> 1669.0807
A6: Wendy's | B6: 550 | C6: LSR | D6: QSR | E6: Burger | F6: 5 | H6: =Table1[[#This Row],[2024 U.S. Sales ($000)]]/SUMIF($E:$E, E6, $G:$G) -> #DIV/0! | I6: =VLOOKUP(Table1[[#This Row],[Chain Name]],[1]Sheet1!A$3:G$26,7,0) -> #N/A | J6: =Table1[[#This Row],[2024 U.S. Sales ($000)]]/Table1[[#This Row],[2024 U.S. Units]] -> #N/A | K6: =Table1[[#This Row],[2024 U.S. Units]]/Table1[[#This Row],[2023 U.S. Units]]-1 -> #N/A | L6: =_xlfn.RRI(5,Table1[[#This Row],[2019 U.S. Sales ($000)]],Table1[[#This Row],[2024 U.S. Sales ($000)]]) -> -1 | M6: =(Table1[[#This Row],[2024 Market share (%)]]-Table1[[#This Row],[2019 Market share (%)]])*10000 -> #DIV/0! | P6: 12285300 | Q6: =Table1[[#This Row],[2023 U.S. Sales ($000)]]/SUMIF($E:$E, E6, $P:$P) -> 0.11221188 | R6: =(Table1[[#This Row],[2023 Market share (%)]]-Table1[[#This Row],[2022 Market share (%)]])*10000 -> -22.476377 | S6: 0.050528458 | T6: 6030 | U6: =P6/T6 -> 2037.3632 | V6: 0.006006006 | W6: =_xlfn.RRI(4,AM6,P6) -> 0.04719177 | X6: =(Table1[[#This Row],[2023 Market share (%)]]-Table1[[#This Row],[2019 Market share (%)]])*10000 -> -58.806835 | Y6: =_xlfn.RRI(4,AP6,U6) -> 0.039376688 | Z6: =_xlfn.RRI(4,AO6,T6) -> 0.0075190087 | AA6: 11694400 | AB6: =Table1[[#This Row],[2022 U.S. Sales ($000)]]/SUMIF($E:$E, E6, $AA:$AA) -> 0.11445952 | AC6: 5994 | AD6: =AA6/AC6 -> 1951.0177 | AE6: 11110700 | AF6: =Table1[[#This Row],[2021 U.S. Sales ($000)]]/SUMIF($E:$E, E6, $AE:$AE) -> 0.11419817 | AG6: 5938 | AH6: =AE6/AG6 -> 1871.1182 | AI6: 10231300 | AJ6: =Table1[[#This Row],[2020 U.S. Sales ($000)]]/SUMIF($E:$E, E6, $AI:$AI) -> 0.11708523 | AK6: 5881 | AL6: =AI6/AK6 -> 1739.7211 | AM6: 10216000 | AN6: =Table1[[#This Row],[2019 U.S. Sales ($000)]]/SUMIF($E:$E, E6, $AM:$AM) -> 0.11809256 | AO6: 5852 | AP6: =AM6/AO6 -> 1745.728
A7: Scooter's Coffee | B7: 5951 | C7: LSR | D7: QSR | E7: Coffee Cafe | F7: 98 | G7: 723000 | H7: =Table1[[#This Row],[2024 U.S. Sales ($000)]]/SUMIF($E:$E, E7, $G:$G) -> 0.014308044 | I7: 849 | J7: =Table1[[#This Row],[2024 U.S. Sales ($000)]]/Table1[[#This Row],[2024 U.S. Units]] -> 851.59011 | K7: =Table1[[#This Row],[2024 U.S. Units]]/Table1[[#This Row],[2023 U.S. Units]]-1 -> 0.132 | L7: =_xlfn.RRI(5,Table1[[#This Row],[2019 U.S. Sales ($000)]],Table1[[#This Row],[2024 U.S. Sales ($000)]]) -> 0.35073592 | M7: =(Table1[[#This Row],[2024 Market share (%)]]-Table1[[#This Row],[2019 Market share (%)]])*10000 -> 97.118728 | P7: 561316 | Q7: =Table1[[#This Row],[2023 U.S. Sales ($000)]]/SUMIF($E:$E, E7, $P:$P) -> 0.011449914 | R7: =(Table1[[#This Row],[2023 Market share (%)]]-Table1[[#This Row],[2022 Market share (%)]])*10000 -> 23.945026 | S7: 0.4087489 | T7: 750 | U7: =P7/T7 -> 748.42133 | V7: 0.35135135 | W7: =_xlfn.RRI(4,AM7,P7) -> 0.36687986 | X7: =(Table1[[#This Row],[2023 Market share (%)]]-Table1[[#This Row],[2019 Market share (%)]])*10000 -> 68.537432 | Z7: =_xlfn.RRI(4,AO7,T7) -> 0.29826794 | AA7: 398450 | AB7: =Table1[[#This Row],[2022 U.S. Sales ($000)]]/SUMIF($E:$E, E7, $AA:$AA) -> 0.0090554118 | AC7: 555 | AD7: =AA7/AC7 -> 717.92793 | AE7: 262800 | AF7: =Table1[[#This Row],[2021 U.S. Sales ($000)]]/SUMIF($E:$E, E7, $AE:$AE) -> 0.0067714351 | AG7: 400 | AH7: =AE7/AG7 -> 657 | AI7: 168100 | AJ7: =Table1[[#This Row],[2020 U.S. Sales ($000)]]/SUMIF($E:$E, E7, $AI:$AI) -> 0.0054210863 | AK7: 308 | AL7: =AI7/AK7 -> 545.77922 | AM7: 160800 | AN7: =Table1[[#This Row],[2019 U.S. Sales ($000)]]/SUMIF($E:$E, E7, $AM:$AM) -> 0.0045961712 | AO7: 264 | AP7: =AM7/AO7 -> 609.09091
A8: Burger King | B8: 232 | C8: LSR | D8: QSR | E8: Burger | F8: 7 | H8: =Table1[[#This Row],[2024 U.S. Sales ($000)]]/SUMIF($E:$E, E8, $G:$G) -> #DIV/0! | I8: =VLOOKUP(Table1[[#This Row],[Chain Name]],[1]Sheet1!A$3:G$26,7,0) -> #N/A | J8: =Table1[[#This Row],[2024 U.S. Sales ($000)]]/Table1[[#This Row],[2024 U.S. Units]] -> #N/A | K8: =Table1[[#This Row],[2024 U.S. Units]]/Table1[[#This Row],[2023 U.S. Units]]-1 -> #N/A | L8: =_xlfn.RRI(5,Table1[[#This Row],[2019 U.S. Sales ($000)]],Table1[[#This Row],[2024 U.S. Sales ($000)]]) -> -1 | M8: =(Table1[[#This Row],[2024 Market share (%)]]-Table1[[#This Row],[2019 Market share (%)]])*10000 -> #DIV/0! | P8: 10957000 | Q8: =Table1[[#This Row],[2023 U.S. Sales ($000)]]/SUMIF($E:$E, E8, $P:$P) -> 0.10007941 | R8: =(Table1[[#This Row],[2023 Market share (%)]]-Table1[[#This Row],[2022 Market share (%)]])*10000 -> -5.1702323 | S8: 0.066063436 | T8: 6778 | U8: =P8/T8 -> 1616.5536 | V8: -0.03748935 | W8: =_xlfn.RRI(4,AM8,P8) -> 0.017959039 | X8: =(Table1[[#This Row],[2023 Market share (%)]]-Table1[[#This Row],[2019 Market share (%)]])*10000 -> -178.74439 | Y8: =_xlfn.RRI(4,AP8,U8) -> 0.038646215 | Z8: =_xlfn.RRI(4,AO8,T8) -> -0.019917443 | AA8: 10278000 | AB8: =Table1[[#This Row],[2022 U.S. Sales ($000)]]/SUMIF($E:$E, E8, $AA:$AA) -> 0.10059643 | AC8: 7042 | AD8: =AA8/AC8 -> 1459.5285 | AE8: 10033000 | AF8: =Table1[[#This Row],[2021 U.S. Sales ($000)]]/SUMIF($E:$E, E8, $AE:$AE) -> 0.10312133 | AG8: 7105 | AH8: =AE8/AG8 -> 1412.1042 | AI8: 9657000 | AJ8: =Table1[[#This Row],[2020 U.S. Sales ($000)]]/SUMIF($E:$E, E8, $AI:$AI) -> 0.11051304 | AK8: 7081 | AL8: =AI8/AK8 -> 1363.7904 | AM8: 10204000 | AN8: =Table1[[#This Row],[2019 U.S. Sales ($000)]]/SUMIF($E:$E, E8, $AM:$AM) -> 0.11795385 | AO8: 7346 | AP8: =AM8/AO8 -> 1389.0553
A9: Subway | B9: 435 | C9: LSR | D9: QSR | E9: Sandwich | F9: 8 | H9: =Table1[[#This Row],[2024 U.S. Sales ($000)]]/SUMIF($E:$E, E9, $G:$G) -> #DIV/0! | I9: =VLOOKUP(Table1[[#This Row],[Chain Name]],[1]Sheet1!A$3:G$26,7,0) -> #N/A | J9: =Table1[[#This Row],[2024 U.S. Sales ($000)]]/Table1[[#This Row],[2024 U.S. Units]] -> #N/A | K9: =Table1[[#This Row],[2024 U.S. Units]]/Table1[[#This Row],[2023 U.S. Units]]-1 -> #N/A | L9: =_xlfn.RRI(5,Table1[[#This Row],[2019 U.S. Sales ($000)]],Table1[[#This Row],[2024 U.S. Sales ($000)]]) -> -1 | M9: =(Table1[[#This Row],[2024 Market share (%)]]-Table1[[#This Row],[2019 Market share (%)]])*10000 -> #DIV/0! | P9: 9982800 | Q9: =Table1[[#This Row],[2023 U.S. Sales ($000)]]/SUMIF($E:$E, E9, $P:$P) -> 0.26429848 | R9: =(Table1[[#This Row],[2023 Market share (%)]]-Table1[[#This Row],[2022 Market share (%)]])*10000 -> -89.181775 | S9: 0.021153846 | T9: 20133 | U9: =P9/T9 -> 495.84265 | V9: -0.021529938 | W9: =_xlfn.RRI(4,AM9,P9) -> -0.0053665753 | X9: =(Table1[[#This Row],[2023 Market share (%)]]-Table1[[#This Row],[2019 Market share (%)]])*10000 -> -479.63189 | Y9: =_xlfn.RRI(4,AP9,U9) -> 0.037111867 | Z9: =_xlfn.RRI(4,AO9,T9) -> -0.040958399 | AA9: 9776000 | AB9: =Table1[[#This Row],[2022 U.S. Sales ($000)]]/SUMIF($E:$E, E9, $AA:$AA) -> 0.27321666 | AC9: 20576 | AD9: =AA9/AC9 -> 475.11664 | AE9: 9397300 | AF9: =Table1[[#This Row],[2021 U.S. Sales ($000)]]/SUMIF($E:$E, E9, $AE:$AE) -> 0.28323758 | AG9: 21147 | AH9: =AE9/AG9 -> 444.37982 | AI9: 8318000 | AJ9: =Table1[[#This Row],[2020 U.S. Sales ($000)]]/SUMIF($E:$E, E9, $AI:$AI) -> 0.29207019 | AK9: 22190 | AL9: =AI9/AK9 -> 374.85354 | AM9: 10200000 | AN9: =Table1[[#This Row],[2019 U.S. Sales ($000)]]/SUMIF($E:$E, E9, $AM:$AM) -> 0.31226167 | AO9: 23799 | AP9: =AM9/AO9 -> 428.58944
A10: Chipotle Mexican Grill | B10: 1750 | C10: LSR | D10: FC | E10: Mexican | F10: 9 | H10: =Table1[[#This Row],[2024 U.S. Sales ($000)]]/SUMIF($E:$E, E10, $G:$G) -> #DIV/0! | I10: =VLOOKUP(Table1[[#This Row],[Chain Name]],[1]Sheet1!A$3:G$26,7,0) -> #N/A | J10: =Table1[[#This Row],[2024 U.S. Sales ($000)]]/Table1[[#This Row],[2024 U.S. Units]] -> #N/A | K10: =Table1[[#This Row],[2024 U.S. Units]]/Table1[[#This Row],[2023 U.S. Units]]-1 -> #N/A | L10: =_xlfn.RRI(5,Table1[[#This Row],[2019 U.S. Sales ($000)]],Table1[[#This Row],[2024 U.S. Sales ($000)]]) -> -1 | M10: =(Table1[[#This Row],[2024 Market share (%)]]-Table1[[#This Row],[2019 Market share (%)]])*10000 -> #DIV/0! | P10: 9804124 | Q10: =Table1[[#This Row],[2023 U.S. Sales ($000)]]/SUMIF($E:$E, E10, $P:$P) -> 0.29629696 | R10: =(Table1[[#This Row],[2023 Market share (%)]]-Table1[[#This Row],[2022 Market share (%)]])*10000 -> 137.47233 | S10: 0.14560912 | T10: 3371 | U10: =P10/T10 -> 2908.3726 | V10: 0.077341004 | W10: =_xlfn.RRI(4,AM10,P10) -> 0.15229392 | X10: =(Table1[[#This Row],[2023 Market share (%)]]-Table1[[#This Row],[2019 Market share (%)]])*10000 -> 669.07784 | Y10: =_xlfn.RRI(4,AP10,U10) -> 0.077776005 | Z10: =_xlfn.RRI(4,AO10,T10) -> 0.069140452 | AA10: 8558001 | AB10: =Table1[[#This Row],[2022 U.S. Sales ($000)]]/SUMIF($E:$E, E10, $AA:$AA) -> 0.28254973 | AC10: 3129 | AD10: =AA10/AC10 -> 2735.0594 | AE10: 7457169 | AF10: =Table1[[#This Row],[2021 U.S. Sales ($000)]]/SUMIF($E:$E, E10, $AE:$AE) -> 0.27206755 | AG10: 2918 | AH10: =AE10/AG10 -> 2555.5754 | AI10: 5920545 | AJ10: =Table1[[#This Row],[2020 U.S. Sales ($000)]]/SUMIF($E:$E, E10, $AI:$AI) -> 0.25117242 | AK10: 2724 | AL10: =AI10/AK10 -> 2173.4747 | AM10: 5561036 | AN10: =Table1[[#This Row],[2019 U.S. Sales ($000)]]/SUMIF($E:$E, E10, $AM:$AM) -> 0.22938918 | AO10: 2580 | AP10: =AM10/AO10 -> 2155.4403
A11: Domino's | B11: 808 | C11: LSR | D11: QSR | E11: Pizza | F11: 10 | H11: =Table1[[#This Row],[2024 U.S. Sales ($000)]]/SUMIF($E:$E, E11, $G:$G) -> #DIV/0! | I11: =VLOOKUP(Table1[[#This Row],[Chain Name]],[1]Sheet1!A$3:G$26,7,0) -> #N/A | J11: =Table1[[#This Row],[2024 U.S. Sales ($000)]]/Table1[[#This Row],[2024 U.S. Units]] -> #N/A | K11: =Table1[[#This Row],[2024 U.S. Units]]/Table1[[#This Row],[2023 U.S. Units]]-1 -> #N/A | L11: =_xlfn.RRI(5,Table1[[#This Row],[2019 U.S. Sales ($000)]],Table1[[#This Row],[2024 U.S. Sales ($000)]]) -> -1 | M11: =(Table1[[#This Row],[2024 Market share (%)]]-Table1[[#This Row],[2019 Market share (%)]])*10000 -> #DIV/0! | P11: 9026100 | Q11: =Table1[[#This Row],[2023 U.S. Sales ($000)]]/SUMIF($E:$E, E11, $P:$P) -> 0.29548453 | R11: =(Table1[[#This Row],[2023 Market share (%)]]-Table1[[#This Row],[2022 Market share (%)]])*10000 -> 6.5304236 | S11: 0.031353908 | T11: 6854 | U11: =P11/T11 -> 1316.9098 | V11: 0.025127131 | W11: =_xlfn.RRI(4,AM11,P11) -> 0.063932396 | X11: =(Table1[[#This Row],[2023 Market share (%)]]-Table1[[#This Row],[2019 Market share (%)]])*10000 -> 225.37354 | Y11: =_xlfn.RRI(4,AP11,U11) -> 0.034480375 | Z11: =_xlfn.RRI(4,AO11,T11) -> 0.028470353 | AA11: 8751700 | AB11: =Table1[[#This Row],[2022 U.S. Sales ($000)]]/SUMIF($E:$E, E11, $AA:$AA) -> 0.29483149 | AC11: 6686 | AD11: =AA11/AC11 -> 1308.959 | AE11: 8641400 | AF11: =Table1[[#This Row],[2021 U.S. Sales ($000)]]/SUMIF($E:$E, E11, $AE:$AE) -> 0.29727651 | AG11: 6560 | AH11: =AE11/AG11 -> 1317.2866 | AI11: 8287100 | AJ11: =Table1[[#This Row],[2020 U.S. Sales ($000)]]/SUMIF($E:$E, E11, $AI:$AI) -> 0.30617079 | AK11: 6355 | AL11: =AI11/AK11 -> 1304.0283 | AM11: 7044400 | AN11: =Table1[[#This Row],[2019 U.S. Sales ($000)]]/SUMIF($E:$E, E11, $AM:$AM) -> 0.27294717 | AO11: 6126 | AP11: =AM11/AO11 -> 1149.9184
A12: Panera Bread | B12: 540 | C12: LSR | D12: FC | E12: Sandwich | F12: 11 | H12: =Table1[[#This Row],[2024 U.S. Sales ($000)]]/SUMIF($E:$E, E12, $G:$G) -> #DIV/0! | I12: =VLOOKUP(Table1[[#This Row],[Chain Name]],[1]Sheet1!A$3:G$26,7,0) -> #N/A | J12: =Table1[[#This Row],[2024 U.S. Sales ($000)]]/Table1[[#This Row],[2024 U.S. Units]] -> #N/A | K12: =Table1[[#This Row],[2024 U.S. Units]]/Table1[[#This Row],[2023 U.S. Units]]-1 -> #N/A | L12: =_xlfn.RRI(5,Table1[[#This Row],[2019 U.S. Sales ($000)]],Table1[[#This Row],[2024 U.S. Sales ($000)]]) -> -1 | M12: =(Table1[[#This Row],[2024 Market share (%)]]-Table1[[#This Row],[2019 Market share (%)]])*10000 -> #DIV/0! | P12: 6456368 | Q12: =Table1[[#This Row],[2023 U.S. Sales ($000)]]/SUMIF($E:$E, E12, $P:$P) -> 0.17093483 | R12: =(Table1[[#This Row],[2023 Market share (%)]]-Table1[[#This Row],[2022 Market share (%)]])*10000 -> -48.980008 | S12: 0.026205369 | T12: 2178 | U12: =P12/T12 -> 2964.3563 | V12: 0.021575985 | W12: =_xlfn.RRI(4,AM12,P12) -> 0.016384949 | X12: =(Table1[[#This Row],[2023 Market share (%)]]-Table1[[#This Row],[2019 Market share (%)]])*10000 -> -142.79196 | Y12: =_xlfn.RRI(4,AP12,U12) -> 0.013808541 | Z12: =_xlfn.RRI(4,AO12,T12) -> 0.0025413166 | AA12: 6291497 | AB12: =Table1[[#This Row],[2022 U.S. Sales ($000)]]/SUMIF($E:$E, E12, $AA:$AA) -> 0.17583284 | AC12: 2132 | AD12: =AA12/AC12 -> 2950.9836 | AE12: 5632778 | AF12: =Table1[[#This Row],[2021 U.S. Sales ($000)]]/SUMIF($E:$E, E12, $AE:$AE) -> 0.1697737 | AG12: 2121 | AH12: =AE12/AG12 -> 2655.7181 | AI12: 4984200 | AJ12: =Table1[[#This Row],[2020 U.S. Sales ($000)]]/SUMIF($E:$E, E12, $AI:$AI) -> 0.17501037 | AK12: 2081 | AL12: =AI12/AK12 -> 2395.0985 | AM12: 6050000 | AN12: =Table1[[#This Row],[2019 U.S. Sales ($000)]]/SUMIF($E:$E, E12, $AM:$AM) -> 0.18521403 | AO12: 2156 | AP12: =AM12/AO12 -> 2806.1224
A13: Panda Express | B13: 906 | C13: LSR | D13: FC | E13: Asian/Noodle | F13: 12 | H13: =Table1[[#This Row],[2024 U.S. Sales ($000)]]/SUMIF($E:$E, E13, $G:$G) -> #DIV/0! | I13: =VLOOKUP(Table1[[#This Row],[Chain Name]],[1]Sheet1!A$3:G$26,7,0) -> #N/A | J13: =Table1[[#This Row],[2024 U.S. Sales ($000)]]/Table1[[#This Row],[2024 U.S. Units]] -> #N/A | K13: =Table1[[#This Row],[2024 U.S. Units]]/Table1[[#This Row],[2023 U.S. Units]]-1 -> #N/A | L13: =_xlfn.RRI(5,Table1[[#This Row],[2019 U.S. Sales ($000)]],Table1[[#This Row],[2024 U.S. Sales ($000)]]) -> -1 | M13: =(Table1[[#This Row],[2024 Market share (%)]]-Table1[[#This Row],[2019 Market share (%)]])*10000 -> #DIV/0! | P13: 5885000 | Q13: =Table1[[#This Row],[2023 U.S. Sales ($000)]]/SUMIF($E:$E, E13, $P:$P) -> 0.71261139 | R13: =(Table1[[#This Row],[2023 Market share (%)]]-Table1[[#This Row],[2022 Market share (%)]])*10000 -> 93.696698 | S13: 0.10041137 | T13: 2420 | U13: =P13/T13 -> 2431.8182 | V13: 0.026293469 | W13: =_xlfn.RRI(4,AM13,P13) -> 0.10503498 | X13: =(Table1[[#This Row],[2023 Market share (%)]]-Table1[[#This Row],[2019 Market share (%)]])*10000 -> 362.29719 | Y13: =_xlfn.RRI(4,AP13,U13) -> 0.077048702 | Z13: =_xlfn.RRI(4,AO13,T13) -> 0.025984224 | AA13: 5348000 | AB13: =Table1[[#This Row],[2022 U.S. Sales ($000)]]/SUMIF($E:$E, E13, $AA:$AA) -> 0.70324172 | AC13: 2358 | AD13: =AA13/AC13 -> 2268.0237 | AE13: 4578000 | AF13: =Table1[[#This Row],[2021 U.S. Sales ($000)]]/SUMIF($E:$E, E13, $AE:$AE) -> 0.69101699 | AG13: 2316 | AH13: =AE13/AG13 -> 1976.6839 | AI13: 3817000 | AJ13: =Table1[[#This Row],[2020 U.S. Sales ($000)]]/SUMIF($E:$E, E13, $AI:$AI) -> 0.69590691 | AK13: 2263 | AL13: =AI13/AK13 -> 1686.6991 | AM13: 3946775 | AN13: =Table1[[#This Row],[2019 U.S. Sales ($000)]]/SUMIF($E:$E, E13, $AM:$AM) -> 0.67638167 | AO13: 2184 | AP13: =AM13/AO13 -> 1807.1314
A14: Pizza Hut | B14: 325 | C14: LSR | D14: QSR | E14: Pizza | F14: 13 | H14: =Table1[[#This Row],[2024 U.S. Sales ($000)]]/SUMIF($E:$E, E14, $G:$G) -> #DIV/0! | I14: =VLOOKUP(Table1[[#This Row],[Chain Name]],[1]Sheet1!A$3:G$26,7,0) -> #N/A | J14: =Table1[[#This Row],[2024 U.S. Sales ($000)]]/Table1[[#This Row],[2024 U.S. Units]] -> #N/A | K14: =Table1[[#This Row],[2024 U.S. Units]]/Table1[[#This Row],[2023 U.S. Units]]-1 -> #N/A | L14: =_xlfn.RRI(5,Table1[[#This Row],[2019 U.S. Sales ($000)]],Table1[[#This Row],[2024 U.S. Sales ($000)]]) -> -1 | M14: =(Table1[[#This Row],[2024 Market share (%)]]-Table1[[#This Row],[2019 Market share (%)]])*10000 -> #DIV/0! | P14: 5577000 | Q14: =Table1[[#This Row],[2023 U.S. Sales ($000)]]/SUMIF($E:$E, E14, $P:$P) -> 0.18257245 | R14: =(Table1[[#This Row],[2023 Market share (%)]]-Table1[[#This Row],[2022 Market share (%)]])*10000 -> -22.762469 | S14: 0.016402406 | T14: 6593 | U14: =P14/T14 -> 845.89716 | V14: 0.0048773053 | W14: =_xlfn.RRI(4,AM14,P14) -> 0.00085353057 | X14: =(Table1[[#This Row],[2023 Market share (%)]]-Table1[[#This Row],[2019 Market share (%)]])*10000 -> -327.81643 | Y14: =_xlfn.RRI(4,AP14,U14) -> 0.026879948 | Z14: =_xlfn.RRI(4,AO14,T14) -> -0.025345142 | AA14: 5487000 | AB14: =Table1[[#This Row],[2022 U.S. Sales ($000)]]/SUMIF($E:$E, E14, $AA:$AA) -> 0.1848487 | AC14: 6561 | AD14: =AA14/AC14 -> 836.30544 | AE14: 5509000 | AF14: =Table1[[#This Row],[2021 U.S. Sales ($000)]]/SUMIF($E:$E, E14, $AE:$AE) -> 0.18951747 | AG14: 6548 | AH14: =AE14/AG14 -> 841.3256 | AI14: 5436000 | AJ14: =Table1[[#This Row],[2020 U.S. Sales ($000)]]/SUMIF($E:$E, E14, $AI:$AI) -> 0.20083557 | AK14: 6561 | AL14: =AI14/AK14 -> 828.53224 | AM14: 5558000 | AN14: =Table1[[#This Row],[2019 U.S. Sales ($000)]]/SUMIF($E:$E, E14, $AM:$AM) -> 0.2153541 | AO14: 7306 | AP14: =AM14/AO14 -> 760.74459
A15: Sonic Drive-In | B15: 536 | C15: LSR | D15: QSR | E15: Burger | F15: 14 | H15: =Table1[[#This Row],[2024 U.S. Sales ($000)]]/SUMIF($E:$E, E15, $G:$G) -> #DIV/0! | I15: =VLOOKUP(Table1[[#This Row],[Chain Name]],[1]Sheet1!A$3:G$26,7,0) -> #N/A | J15: =Table1[[#This Row],[2024 U.S. Sales ($000)]]/Table1[[#This Row],[2024 U.S. Units]] -> #N/A | K15: =Table1[[#This Row],[2024 U.S. Units]]/Table1[[#This Row],[2023 U.S. Units]]-1 -> #N/A | L15: =_xlfn.RRI(5,Table1[[#This Row],[2019 U.S. Sales ($000)]],Table1[[#This Row],[2024 U.S. Sales ($000)]]) -> -1 | M15: =(Table1[[#This Row],[2024 Market share (%)]]-Table1[[#This Row],[2019 Market share (%)]])*10000 -> #DIV/0! | P15: 5533582 | Q15: =Table1[[#This Row],[2023 U.S. Sales ($000)]]/SUMIF($E:$E, E15, $P:$P) -> 0.050542815 | R15: =(Table1[[#This Row],[2023 Market share (%)]]-Table1[[#This Row],[2022 Market share (%)]])*10000 -> -32.800158 | S15: 0.0062682848 | T15: 3521 | U15: =P15/T15 -> 1571.5939 | V15: -0.0070501974 | W15: =_xlfn.RRI(4,AM15,P15) -> 0.042365923 | X15: =(Table1[[#This Row],[2023 Market share (%)]]-Table1[[#This Row],[2019 Market share (%)]])*10000 -> -36.407031 | Y15: =_xlfn.RRI(4,AP15,U15) -> 0.042735779 | Z15: =_xlfn.RRI(4,AO15,T15) -> -0.00035469803 | AA15: 5499112 | AB15: =Table1[[#This Row],[2022 U.S. Sales ($000)]]/SUMIF($E:$E, E15, $AA:$AA) -> 0.053822831 | AC15: 3546 | AD15: =AA15/AC15 -> 1550.793 | AE15: 5835448 | AF15: =Table1[[#This Row],[2021 U.S. Sales ($000)]]/SUMIF($E:$E, E15, $AE:$AE) -> 0.059977991 | AG15: 3552 | AH15: =AE15/AG15 -> 1642.8626 | AI15: 5680323 | AJ15: =Table1[[#This Row],[2020 U.S. Sales ($000)]]/SUMIF($E:$E, E15, $AI:$AI) -> 0.065004634 | AK15: 3526 | AL15: =AI15/AK15 -> 1610.9821 | AM15: 4687330 | AN15: =Table1[[#This Row],[2019 U.S. Sales ($000)]]/SUMIF($E:$E, E15, $AM:$AM) -> 0.054183518 | AO15: 3526 | AP15: =AM15/AO15 -> 1329.3619
A16: Popeyes | B16: 526 | C16: LSR | D16: QSR | E16: Chicken | F16: 15 | H16: =Table1[[#This Row],[2024 U.S. Sales ($000)]]/SUMIF($E:$E, E16, $G:$G) -> #DIV/0! | I16: =VLOOKUP(Table1[[#This Row],[Chain Name]],[1]Sheet1!A$3:G$26,7,0) -> #N/A | J16: =Table1[[#This Row],[2024 U.S. Sales ($000)]]/Table1[[#This Row],[2024 U.S. Units]] -> #N/A | K16: =Table1[[#This Row],[2024 U.S. Units]]/Table1[[#This Row],[2023 U.S. Units]]-1 -> #N/A | L16: =_xlfn.RRI(5,Table1[[#This Row],[2019 U.S. Sales ($000)]],Table1[[#This Row],[2024 U.S. Sales ($000)]]) -> -1 | M16: =(Table1[[#This Row],[2024 Market share (%)]]-Table1[[#This Row],[2019 Market share (%)]])*10000 -> #DIV/0! | P16: 5511000 | Q16: =Table1[[#This Row],[2023 U.S. Sales ($000)]]/SUMIF($E:$E, E16, $P:$P) -> 0.11250907 | R16: =(Table1[[#This Row],[2023 Market share (%)]]-Table1[[#This Row],[2022 Market share (%)]])*10000 -> -21.091951 | S16: 0.1019796 | T16: 3051 | U16: =P16/T16 -> 1806.293 | V16: 0.044505306 | W16: =_xlfn.RRI(4,AM16,P16) -> 0.096527126 | X16: =(Table1[[#This Row],[2023 Market share (%)]]-Table1[[#This Row],[2019 Market share (%)]])*10000 -> -116.61727 | Y16: =_xlfn.RRI(4,AP16,U16) -> 0.040750164 | Z16: =_xlfn.RRI(4,AO16,T16) -> 0.053593037 | AA16: 5001000 | AB16: =Table1[[#This Row],[2022 U.S. Sales ($000)]]/SUMIF($E:$E, E16, $AA:$AA) -> 0.11461827 | AC16: 2921 | AD16: =AA16/AC16 -> 1712.0849 | AE16: 4775000 | AF16: =Table1[[#This Row],[2021 U.S. Sales ($000)]]/SUMIF($E:$E, E16, $AE:$AE) -> 0.12145533 | AG16: 2754 | AH16: =AE16/AG16 -> 1733.8417 | AI16: 4587000 | AJ16: =Table1[[#This Row],[2020 U.S. Sales ($000)]]/SUMIF($E:$E, E16, $AI:$AI) -> 0.13563253 | AK16: 2609 | AL16: =AI16/AK16 -> 1758.1449 | AM16: 3812000 | AN16: =Table1[[#This Row],[2019 U.S. Sales ($000)]]/SUMIF($E:$E, E16, $AM:$AM) -> 0.1241708 | AO16: 2476 | AP16: =AM16/AO16 -> 1539.58
A17: KFC | B17: 516 | C17: LSR | D17: QSR | E17: Chicken | F17: 16 | H17: =Table1[[#This Row],[2024 U.S. Sales ($000)]]/SUMIF($E:$E, E17, $G:$G) -> #DIV/0! | I17: =VLOOKUP(Table1[[#This Row],[Chain Name]],[1]Sheet1!A$3:G$26,7,0) -> #N/A | J17: =Table1[[#This Row],[2024 U.S. Sales ($000)]]/Table1[[#This Row],[2024 U.S. Units]] -> #N/A | K17: =Table1[[#This Row],[2024 U.S. Units]]/Table1[[#This Row],[2023 U.S. Units]]-1 -> #N/A | L17: =_xlfn.RRI(5,Table1[[#This Row],[2019 U.S. Sales ($000)]],Table1[[#This Row],[2024 U.S. Sales ($000)]]) -> -1 | M17: =(Table1[[#This Row],[2024 Market share (%)]]-Table1[[#This Row],[2019 Market share (%)]])*10000 -> #DIV/0! | P17: 5176000 | Q17: =Table1[[#This Row],[2023 U.S. Sales ($000)]]/SUMIF($E:$E, E17, $P:$P) -> 0.10566993 | R17: =(Table1[[#This Row],[2023 Market share (%)]]-Table1[[#This Row],[2022 Market share (%)]])*10000 -> -109.19382 | S17: 0.017495577 | T17: 3791 | U17: =P17/T17 -> 1365.339 | V17: -0.032414497 | W17: =_xlfn.RRI(4,AM17,P17) -> 0.032978326 | X17: =(Table1[[#This Row],[2023 Market share (%)]]-Table1[[#This Row],[2019 Market share (%)]])*10000 -> -424.09942 | Y17: =_xlfn.RRI(4,AP17,U17) -> 0.051157759 | Z17: =_xlfn.RRI(4,AO17,T17) -> -0.017294677 | AA17: 5087000 | AB17: =Table1[[#This Row],[2022 U.S. Sales ($000)]]/SUMIF($E:$E, E17, $AA:$AA) -> 0.11658931 | AC17: 3918 | AD17: =AA17/AC17 -> 1298.3665 | AE17: 5079000 | AF17: =Table1[[#This Row],[2021 U.S. Sales ($000)]]/SUMIF($E:$E, E17, $AE:$AE) -> 0.12918777 | AG17: 3953 | AH17: =AE17/AG17 -> 1284.847 | AI17: 4742000 | AJ17: =Table1[[#This Row],[2020 U.S. Sales ($000)]]/SUMIF($E:$E, E17, $AI:$AI) -> 0.14021571 | AK17: 3943 | AL17: =AI17/AK17 -> 1202.6376 | AM17: 4546000 | AN17: =Table1[[#This Row],[2019 U.S. Sales ($000)]]/SUMIF($E:$E, E17, $AM:$AM) -> 0.14807987 | AO17: 4065 | AP17: =AM17/AO17 -> 1118.3272
A18: Olive Garden | B18: 433 | C18: FSR | D18: CDR | E18: Italian/Pizza | F18: 17 | H18: =Table1[[#This Row],[2024 U.S. Sales ($000)]]/SUMIF($E:$E, E18, $G:$G) -> #DIV/0! | I18: =VLOOKUP(Table1[[#This Row],[Chain Name]],[1]Sheet1!A$3:G$26,7,0) -> #N/A | J18: =Table1[[#This Row],[2024 U.S. Sales ($000)]]/Table1[[#This Row],[2024 U.S. Units]] -> #N/A | K18: =Table1[[#This Row],[2024 U.S. Units]]/Table1[[#This Row],[2023 U.S. Units]]-1 -> #N/A | L18: =_xlfn.RRI(5,Table1[[#This Row],[2019 U.S. Sales ($000)]],Table1[[#This Row],[2024 U.S. Sales ($000)]]) -> -1 | M18: =(Table1[[#This Row],[2024 Market share (%)]]-Table1[[#This Row],[2019 Market share (%)]])*10000 -> #DIV/0! | P18: 5112400 | Q18: =Table1[[#This Row],[2023 U.S. Sales ($000)]]/SUMIF($E:$E, E18, $P:$P) -> 0.53198735 | R18: =(Table1[[#This Row],[2023 Market share (%)]]-Table1[[#This Row],[2022 Market share (%)]])*10000 -> 205.47069 | S18: 0.088439429 | T18: 908 | U18: =P18/T18 -> 5630.3965 | V18: 0.02367531 | W18: =_xlfn.RRI(4,AM18,P18) -> 0.039471222 | X18: =(Table1[[#This Row],[2023 Market share (%)]]-Table1[[#This Row],[2019 Market share (%)]])*10000 -> 519.01429 | Z18: =_xlfn.RRI(4,AO18,T18) -> 0.011910236 | AA18: 4697000 | AB18: =Table1[[#This Row],[2022 U.S. Sales ($000)]]/SUMIF($E:$E, E18, $AA:$AA) -> 0.51144028 | AC18: 887 | AD18: =AA18/AC18 -> 5295.3777 | AE18: 4181700 | AF18: =Table1[[#This Row],[2021 U.S. Sales ($000)]]/SUMIF($E:$E, E18, $AE:$AE) -> 0.49940037 | AG18: 876 | AH18: =AE18/AG18 -> 4773.6301 | AI18: 3544400 | AJ18: =Table1[[#This Row],[2020 U.S. Sales ($000)]]/SUMIF($E:$E, E18, $AI:$AI) -> 0.51376463 | AK18: 868 | AL18: =AI18/AK18 -> 4083.4101 | AM18: 4379000 | AN18: =Table1[[#This Row],[2019 U.S. Sales ($000)]]/SUMIF($E:$E, E18, $AM:$AM) -> 0.48008592 | AO18: 866 | AP18: =AM18/AO18 -> 5056.582
A19: Dairy Queen | B19: 491 | C19: LSR | D19: QSR | E19: Frozen Desserts | F19: 18 | H19: =Table1[[#This Row],[2024 U.S. Sales ($000)]]/SUMIF($E:$E, E19, $G:$G) -> #DIV/0! | I19: =VLOOKUP(Table1[[#This Row],[Chain Name]],[1]Sheet1!A$3:G$26,7,0) -> #N/A | J19: =Table1[[#This Row],[2024 U.S. Sales ($000)]]/Table1[[#This Row],[2024 U.S. Units]] -> #N/A | K19: =Table1[[#This Row],[2024 U.S. Units]]/Table1[[#This Row],[2023 U.S. Units]]-1 -> #N/A | L19: =_xlfn.RRI(5,Table1[[#This Row],[2019 U.S. Sales ($000)]],Table1[[#This Row],[2024 U.S. Sales ($000)]]) -> -1 | M19: =(Table1[[#This Row],[2024 Market share (%)]]-Table1[[#This Row],[2019 Market share (%)]])*10000 -> #DIV/0! | P19: 4967664 | Q19: =Table1[[#This Row],[2023 U.S. Sales ($000)]]/SUMIF($E:$E, E19, $P:$P) -> 0.61225118 | R19: =(Table1[[#This Row],[2023 Market share (%)]]-Table1[[#This Row],[2022 Market share (%)]])*10000 -> 41.199828 | S19: 0.084866163 | T19: 4254 | U19: =P19/T19 -> 1167.763 | V19: -0.012305549 | W19: =_xlfn.RRI(4,AM19,P19) -> 0.07208879 | X19: =(Table1[[#This Row],[2023 Market share (%)]]-Table1[[#This Row],[2019 Market share (%)]])*10000 -> 199.90281 | Y19: =_xlfn.RRI(4,AP19,U19) -> 0.080002341 | Z19: =_xlfn.RRI(4,AO19,T19) -> -0.0073273462 | AA19: 4579057 | AB19: =Table1[[#This Row],[2022 U.S. Sales ($000)]]/SUMIF($E:$E, E19, $AA:$AA) -> 0.60813119 | AC19: 4307 | AD19: =AA19/AC19 -> 1063.1662 | AE19: 4493655 | AF19: =Table1[[#This Row],[2021 U.S. Sales ($000)]]/SUMIF($E:$E, E19, $AE:$AE) -> 0.61548048 | AG19: 4339 | AH19: =AE19/AG19 -> 1035.643 | AI19: 3981900 | AJ19: =Table1[[#This Row],[2020 U.S. Sales ($000)]]/SUMIF($E:$E, E19, $AI:$AI) -> 0.62312467 | AK19: 4361 | AL19: =AI19/AK19 -> 913.0704 | AM19: 3760358 | AN19: =Table1[[#This Row],[2019 U.S. Sales ($000)]]/SUMIF($E:$E, E19, $AM:$AM) -> 0.5922609 | AO19: 4381 | AP19: =AM19/AO19 -> 858.33326
A20: Texas Roadhouse | B20: 2403 | C20: FSR | D20: CDR | E20: Steak | F20: 19 | H20: =Table1[[#This Row],[2024 U.S. Sales ($000)]]/SUMIF($E:$E, E20, $G:$G) -> #DIV/0! | I20: =VLOOKUP(Table1[[#This Row],[Chain Name]],[1]Sheet1!A$3:G$26,7,0) -> #N/A | J20: =Table1[[#This Row],[2024 U.S. Sales ($000)]]/Table1[[#This Row],[2024 U.S. Units]] -> #N/A | K20: =Table1[[#This Row],[2024 U.S. Units]]/Table1[[#This Row],[2023 U.S. Units]]-1 -> #N/A | L20: =_xlfn.RRI(5,Table1[[#This Row],[2019 U.S. Sales ($000)]],Table1[[#This Row],[2024 U.S. Sales ($000)]]) -> -1 | M20: =(Table1[[#This Row],[2024 Market share (%)]]-Table1[[#This Row],[2019 Market share (%)]])*10000 -> #DIV/0! | P20: 4783923 | Q20: =Table1[[#This Row],[2023 U.S. Sales ($000)]]/SUMIF($E:$E, E20, $P:$P) -> 0.29964754 | R20: =(Table1[[#This Row],[2023 Market share (%)]]-Table1[[#This Row],[2022 Market share (%)]])*10000 -> 124.60386 | S20: 0.13849148 | T20: 638 | U20: =P20/T20 -> 7498.3119 | V20: 0.039087948 | W20: =_xlfn.RRI(4,AM20,P20) -> 0.1222061 | X20: =(Table1[[#This Row],[2023 Market share (%)]]-Table1[[#This Row],[2019 Market share (%)]])*10000 -> 590.81675 | Z20: =_xlfn.RRI(4,AO20,T20) -> 0.036391606 | AA20: 4201984 | AB20: =Table1[[#This Row],[2022 U.S. Sales ($000)]]/SUMIF($E:$E, E20, $AA:$AA) -> 0.28718715 | AC20: 614 | AD20: =AA20/AC20 -> 6843.6221 | AE20: 3713089 | AF20: =Table1[[#This Row],[2021 U.S. Sales ($000)]]/SUMIF($E:$E, E20, $AE:$AE) -> 0.28567816 | AG20: 596 | AH20: =AE20/AG20 -> 6230.0151 | AI20: 2615115 | AJ20: =Table1[[#This Row],[2020 U.S. Sales ($000)]]/SUMIF($E:$E, E20, $AI:$AI) -> 0.27845546 | AK20: 572 | AL20: =AI20/AK20 -> 4571.8794 | AM20: 3016433 | AN20: =Table1[[#This Row],[2019 U.S. Sales ($000)]]/SUMIF($E:$E, E20, $AM:$AM) -> 0.24056586 | AO20: 553 | AP20: =AM20/AO20 -> 5454.6709
A21: Arby's | B21: 463 | C21: LSR | D21: QSR | E21: Sandwich | F21: 20 | H21: =Table1[[#This Row],[2024 U.S. Sales ($000)]]/SUMIF($E:$E, E21, $G:$G) -> #DIV/0! | I21: =VLOOKUP(Table1[[#This Row],[Chain Name]],[1]Sheet1!A$3:G$26,7,0) -> #N/A | J21: =Table1[[#This Row],[2024 U.S. Sales ($000)]]/Table1[[#This Row],[2024 U.S. Units]] -> #N/A | K21: =Table1[[#This Row],[2024 U.S. Units]]/Table1[[#This Row],[2023 U.S. Units]]-1 -> #N/A | L21: =_xlfn.RRI(5,Table1[[#This Row],[2019 U.S. Sales ($000)]],Table1[[#This Row],[2024 U.S. Sales ($000)]]) -> -1 | M21: =(Table1[[#This Row],[2024 Market share (%)]]-Table1[[#This Row],[2019 Market share (%)]])*10000 -> #DIV/0! | P21: 4616904 | Q21: =Table1[[#This Row],[2023 U.S. Sales ($000)]]/SUMIF($E:$E, E21, $P:$P) -> 0.12223432 | R21: =(Table1[[#This Row],[2023 Market share (%)]]-Table1[[#This Row],[2022 Market share (%)]])*10000 -> -45.165277 | S21: 0.01799577 | T21: 3413 | U21: =P21/T21 -> 1352.7407 | V21: -0.00058565154 | W21: =_xlfn.RRI(4,AM21,P21) -> 0.044111652 | X21: =(Table1[[#This Row],[2023 Market share (%)]]-Table1[[#This Row],[2019 Market share (%)]])*10000 -> 33.070085 | Y21: =_xlfn.RRI(4,AP21,U21) -> 0.039956973 | Z21: =_xlfn.RRI(4,AO21,T21) -> 0.0039950488 | AA21: 4535288 | AB21: =Table1[[#This Row],[2022 U.S. Sales ($000)]]/SUMIF($E:$E, E21, $AA:$AA) -> 0.12675084 | AC21: 3415 | AD21: =AA21/AC21 -> 1328.0492 | AE21: 4462374 | AF21: =Table1[[#This Row],[2021 U.S. Sales ($000)]]/SUMIF($E:$E, E21, $AE:$AE) -> 0.13449736 | AG21: 3409 | AH21: =AE21/AG21 -> 1308.9979 | AI21: 4214876 | AJ21: =Table1[[#This Row],[2020 U.S. Sales ($000)]]/SUMIF($E:$E, E21, $AI:$AI) -> 0.14799707 | AK21: 3369 | AL21: =AI21/AK21 -> 1251.0763 | AM21: 3884750 | AN21: =Table1[[#This Row],[2019 U.S. Sales ($000)]]/SUMIF($E:$E, E21, $AM:$AM) -> 0.11892731 | AO21: 3359 | AP21: =AM21/AO21 -> 1156.5198
A22: Little Caesars | B22: 821 | C22: LSR | D22: QSR | E22: Pizza | F22: 21 | H22: =Table1[[#This Row],[2024 U.S. Sales ($000)]]/SUMIF($E:$E, E22, $G:$G) -> #DIV/0! | I22: =VLOOKUP(Table1[[#This Row],[Chain Name]],[1]Sheet1!A$3:G$26,7,0) -> #N/A | J22: =Table1[[#This Row],[2024 U.S. Sales ($000)]]/Table1[[#This Row],[2024 U.S. Units]] -> #N/A | K22: =Table1[[#This Row],[2024 U.S. Units]]/Table1[[#This Row],[2023 U.S. Units]]-1 -> #N/A | L22: =_xlfn.RRI(5,Table1[[#This Row],[2019 U.S. Sales ($000)]],Table1[[#This Row],[2024 U.S. Sales ($000)]]) -> -1 | M22: =(Table1[[#This Row],[2024 Market share (%)]]-Table1[[#This Row],[2019 Market share (%)]])*10000 -> #DIV/0! | P22: 4451200 | Q22: =Table1[[#This Row],[2023 U.S. Sales ($000)]]/SUMIF($E:$E, E22, $P:$P) -> 0.1457175 | R22: =(Table1[[#This Row],[2023 Market share (%)]]-Table1[[#This Row],[2022 Market share (%)]])*10000 -> 7.7954549 | S22: 0.034609395 | T22: 4217 | U22: =P22/T22 -> 1055.5371 | V22: 0.010543973 | W22: =_xlfn.RRI(4,AM22,P22) -> 0.039393026 | X22: =(Table1[[#This Row],[2023 Market share (%)]]-Table1[[#This Row],[2019 Market share (%)]])*10000 -> -20.546208 | Y22: =_xlfn.RRI(4,AP22,U22) -> 0.039208119 | Z22: =_xlfn.RRI(4,AO22,T22) -> 0.00017793067 | AA22: 4302300 | AB22: =Table1[[#This Row],[2022 U.S. Sales ($000)]]/SUMIF($E:$E, E22, $AA:$AA) -> 0.14493796 | AC22: 4173 | AD22: =AA22/AC22 -> 1030.9849 | AE22: 4233500 | AF22: =Table1[[#This Row],[2021 U.S. Sales ($000)]]/SUMIF($E:$E, E22, $AE:$AE) -> 0.14563845 | AG22: 4181 | AH22: =AE22/AG22 -> 1012.5568 | AI22: 3985000 | AJ22: =Table1[[#This Row],[2020 U.S. Sales ($000)]]/SUMIF($E:$E, E22, $AI:$AI) -> 0.14722769 | AK22: 4209 | AL22: =AI22/AK22 -> 946.78071 | AM22: 3813800 | AN22: =Table1[[#This Row],[2019 U.S. Sales ($000)]]/SUMIF($E:$E, E22, $AM:$AM) -> 0.14777212 | AO22: 4214 | AP22: =AM22/AO22 -> 905.03085
A23: Jack in the Box | B23: 514 | C23: LSR | D23: QSR | E23: Burger | F23: 22 | H23: =Table1[[#This Row],[2024 U.S. Sales ($000)]]/SUMIF($E:$E, E23, $G:$G) -> #DIV/0! | I23: =VLOOKUP(Table1[[#This Row],[Chain Name]],[1]Sheet1!A$3:G$26,7,0) -> #N/A | J23: =Table1[[#This Row],[2024 U.S. Sales ($000)]]/Table1[[#This Row],[2024 U.S. Units]] -> #N/A | K23: =Table1[[#This Row],[2024 U.S. Units]]/Table1[[#This Row],[2023 U.S. Units]]-1 -> #N/A | L23: =_xlfn.RRI(5,Table1[[#This Row],[2019 U.S. Sales ($000)]],Table1[[#This Row],[2024 U.S. Sales ($000)]]) -> -1 | M23: =(Table1[[#This Row],[2024 Market share (%)]]-Table1[[#This Row],[2019 Market share (%)]])*10000 -> #DIV/0! | P23: 4419733 | Q23: =Table1[[#This Row],[2023 U.S. Sales ($000)]]/SUMIF($E:$E, E23, $P:$P) -> 0.040369104 | R23: =(Table1[[#This Row],[2023 Market share (%)]]-Table1[[#This Row],[2022 Market share (%)]])*10000 -> 1.32077 | S23: 0.075088262 | T23: 2186 | U23: =P23/T23 -> 2021.8358 | V23: 0.0022925264 | W23: =_xlfn.RRI(4,AM23,P23) -> 0.059706163 | X23: =(Table1[[#This Row],[2023 Market share (%)]]-Table1[[#This Row],[2019 Market share (%)]])*10000 -> -1.4403219 | Y23: =_xlfn.RRI(4,AP23,U23) -> 0.066547591 | Z23: =_xlfn.RRI(4,AO23,T23) -> -0.0064145548 | AA23: 4111042 | AB23: =Table1[[#This Row],[2022 U.S. Sales ($000)]]/SUMIF($E:$E, E23, $AA:$AA) -> 0.040237027 | AC23: 2181 | AD23: =AA23/AC23 -> 1884.9344 | AE23: 4155340 | AF23: =Table1[[#This Row],[2021 U.S. Sales ($000)]]/SUMIF($E:$E, E23, $AE:$AE) -> 0.042709479 | AG23: 2218 | AH23: =AE23/AG23 -> 1873.4626 | AI23: 3672732 | AJ23: =Table1[[#This Row],[2020 U.S. Sales ($000)]]/SUMIF($E:$E, E23, $AI:$AI) -> 0.04203011 | AK23: 2241 | AL23: =AI23/AK23 -> 1638.8809 | AM23: 3504727 | AN23: =Table1[[#This Row],[2019 U.S. Sales ($000)]]/SUMIF($E:$E, E23, $AM:$AM) -> 0.040513136 | AO23: 2243 | AP23: =AM23/AO23 -> 1562.5176
A24: Applebee's | B24: 1029 | C24: FSR | D24: CDR | E24: Varied Menu | F24: 23 | H24: =Table1[[#This Row],[2024 U.S. Sales ($000)]]/SUMIF($E:$E, E24, $G:$G) -> #DIV/0! | I24: =VLOOKUP(Table1[[#This Row],[Chain Name]],[1]Sheet1!A$3:G$26,7,0) -> #N/A | J24: =Table1[[#This Row],[2024 U.S. Sales ($000)]]/Table1[[#This Row],[2024 U.S. Units]] -> #N/A | K24: =Table1[[#This Row],[2024 U.S. Units]]/Table1[[#This Row],[2023 U.S. Units]]-1 -> #N/A | L24: =_xlfn.RRI(5,Table1[[#This Row],[2019 U.S. Sales ($000)]],Table1[[#This Row],[2024 U.S. Sales ($000)]]) -> -1 | M24: =(Table1[[#This Row],[2024 Market share (%)]]-Table1[[#This Row],[2019 Market share (%)]])*10000 -> #DIV/0! | P24: 4356600 | Q24: =Table1[[#This Row],[2023 U.S. Sales ($000)]]/SUMIF($E:$E, E24, $P:$P) -> 0.18060178 | R24: =(Table1[[#This Row],[2023 Market share (%)]]-Table1[[#This Row],[2022 Market share (%)]])*10000 -> -48.825699 | S24: -0.0012379642 | T24: 1536 | U24: =P24/T24 -> 2836.3281 | V24: -0.021032505 | W24: =_xlfn.RRI(4,AM24,P24) -> 0.016191641 | X24: =(Table1[[#This Row],[2023 Market share (%)]]-Table1[[#This Row],[2019 Market share (%)]])*10000 -> 17.024499 | Z24: =_xlfn.RRI(4,AO24,T24) -> -0.019959001 | AA24: 4362000 | AB24: =Table1[[#This Row],[2022 U.S. Sales ($000)]]/SUMIF($E:$E, E24, $AA:$AA) -> 0.18548435 | AC24: 1569 | AD24: =AA24/AC24 -> 2780.1147 | AE24: 4167700 | AF24: =Table1[[#This Row],[2021 U.S. Sales ($000)]]/SUMIF($E:$E, E24, $AE:$AE) -> 0.19188213 | AG24: 1578 | AH24: =AE24/AG24 -> 2641.128 | AI24: 3101000 | AJ24: =Table1[[#This Row],[2020 U.S. Sales ($000)]]/SUMIF($E:$E, E24, $AI:$AI) -> 0.19017193 | AK24: 1598 | AL24: =AI24/AK24 -> 1940.5507 | AM24: 4085500 | AN24: =Table1[[#This Row],[2019 U.S. Sales ($000)]]/SUMIF($E:$E, E24, $AM:$AM) -> 0.17889933 | AO24: 1665 | AP24: =AM24/AO24 -> 2453.7538
A25: Chili's Grill & Bar | B25: 482 | C25: FSR | D25: CDR | E25: Varied Menu | F25: 24 | H25: =Table1[[#This Row],[2024 U.S. Sales ($000)]]/SUMIF($E:$E, E25, $G:$G) -> #DIV/0! | I25: =VLOOKUP(Table1[[#This Row],[Chain Name]],[1]Sheet1!A$3:G$26,7,0) -> #N/A | J25: =Table1[[#This Row],[2024 U.S. Sales ($000)]]/Table1[[#This Row],[2024 U.S. Units]] -> #N/A | K25: =Table1[[#This Row],[2024 U.S. Units]]/Table1[[#This Row],[2023 U.S. Units]]-1 -> #N/A | L25: =_xlfn.RRI(5,Table1[[#This Row],[2019 U.S. Sales ($000)]],Table1[[#This Row],[2024 U.S. Sales ($000)]]) -> -1 | M25: =(Table1[[#This Row],[2024 Market share (%)]]-Table1[[#This Row],[2019 Market share (%)]])*10000 -> #DIV/0! | P25: 4023300 | Q25: =Table1[[#This Row],[2023 U.S. Sales ($000)]]/SUMIF($E:$E, E25, $P:$P) -> 0.16678491 | R25: =(Table1[[#This Row],[2023 Market share (%)]]-Table1[[#This Row],[2022 Market share (%)]])*10000 -> 58.74473 | S25: 0.06321186 | T25: 1230 | U25: =P25/T25 -> 3270.9756 | V25: 0.0024449878 | W25: =_xlfn.RRI(4,AM25,P25) -> 0.043979102 | X25: =(Table1[[#This Row],[2023 Market share (%)]]-Table1[[#This Row],[2019 Market share (%)]])*10000 -> 184.72089 | Z25: =_xlfn.RRI(4,AO25,T25) -> -0.002022255 | AA25: 3784100 | AB25: =Table1[[#This Row],[2022 U.S. Sales ($000)]]/SUMIF($E:$E, E25, $AA:$AA) -> 0.16091044 | AC25: 1227 | AD25: =AA25/AC25 -> 3084.0261 | AE25: 3585800 | AF25: =Table1[[#This Row],[2021 U.S. Sales ($000)]]/SUMIF($E:$E, E25, $AE:$AE) -> 0.16509128 | AG25: 1234 | AH25: =AE25/AG25 -> 2905.8347 | AI25: 2930000 | AJ25: =Table1[[#This Row],[2020 U.S. Sales ($000)]]/SUMIF($E:$E, E25, $AI:$AI) -> 0.17968519 | AK25: 1232 | AL25: =AI25/AK25 -> 2378.2468 | AM25: 3387000 | AN25: =Table1[[#This Row],[2019 U.S. Sales ($000)]]/SUMIF($E:$E, E25, $AM:$AM) -> 0.14831282 | AO25: 1240 | AP25: =AM25/AO25 -> 2731.4516
A26: Buffalo Wild Wings | B26: 1588 | C26: FSR | D26: CDR | E26: Sports Bar | F26: 25 | H26: =Table1[[#This Row],[2024 U.S. Sales ($000)]]/SUMIF($E:$E, E26, $G:$G) -> #DIV/0! | I26: =VLOOKUP(Table1[[#This Row],[Chain Name]],[1]Sheet1!A$3:G$26,7,0) -> #N/A | J26: =Table1[[#This Row],[2024 U.S. Sales ($000)]]/Table1[[#This Row],[2024 U.S. Units]] -> #N/A | K26: =Table1[[#This Row],[2024 U.S. Units]]/Table1[[#This Row],[2023 U.S. Units]]-1 -> #N/A | L26: =_xlfn.RRI(5,Table1[[#This Row],[2019 U.S. Sales ($000)]],Table1[[#This Row],[2024 U.S. Sales ($000)]]) -> -1 | M26: =(Table1[[#This Row],[2024 Market share (%)]]-Table1[[#This Row],[2019 Market share (%)]])*10000 -> #DIV/0! | P26: 3958425 | Q26: =Table1[[#This Row],[2023 U.S. Sales ($000)]]/SUMIF($E:$E, E26, $P:$P) -> 0.40595463 | R26: =(Table1[[#This Row],[2023 Market share (%)]]-Table1[[#This Row],[2022 Market share (%)]])*10000 -> -145.74108 | S26: 0.0053336903 | T26: 1264 | U26: =P26/T26 -> 3131.6653 | V26: 0.017713366 | W26: =_xlfn.RRI(4,AM26,P26) -> 0.019124182 | X26: =(Table1[[#This Row],[2023 Market share (%)]]-Table1[[#This Row],[2019 Market share (%)]])*10000 -> -227.89789 | Z26: =_xlfn.RRI(4,AO26,T26) -> 0.01181227 | AA26: 3937424 | AB26: =Table1[[#This Row],[2022 U.S. Sales ($000)]]/SUMIF($E:$E, E26, $AA:$AA) -> 0.42052873 | AC26: 1242 | AD26: =AA26/AC26 -> 3170.2287 | AE26: 3740250 | AF26: =Table1[[#This Row],[2021 U.S. Sales ($000)]]/SUMIF($E:$E, E26, $AE:$AE) -> 0.43855597 | AG26: 1212 | AH26: =AE26/AG26 -> 3086.0149 | AI26: 3163919 | AJ26: =Table1[[#This Row],[2020 U.S. Sales ($000)]]/SUMIF($E:$E, E26, $AI:$AI) -> 0.47753282 | AK26: 1170 | AL26: =AI26/AK26 -> 2704.2043 | AM26: 3669560 | AN26: =Table1[[#This Row],[2019 U.S. Sales ($000)]]/SUMIF($E:$E, E26, $AM:$AM) -> 0.42874442 | AO26: 1206 | AP26: =AM26/AO26 -> 3042.7529
A27: Papa Johns | B27: 834 | C27: LSR | D27: QSR | E27: Pizza | F27: 26 | H27: =Table1[[#This Row],[2024 U.S. Sales ($000)]]/SUMIF($E:$E, E27, $G:$G) -> #DIV/0! | I27: =VLOOKUP(Table1[[#This Row],[Chain Name]],[1]Sheet1!A$3:G$26,7,0) -> #N/A | J27: =Table1[[#This Row],[2024 U.S. Sales ($000)]]/Table1[[#This Row],[2024 U.S. Units]] -> #N/A | K27: =Table1[[#This Row],[2024 U.S. Units]]/Table1[[#This Row],[2023 U.S. Units]]-1 -> #N/A | L27: =_xlfn.RRI(5,Table1[[#This Row],[2019 U.S. Sales ($000)]],Table1[[#This Row],[2024 U.S. Sales ($000)]]) -> -1 | M27: =(Table1[[#This Row],[2024 Market share (%)]]-Table1[[#This Row],[2019 Market share (%)]])*10000 -> #DIV/0! | P27: 3816400 | Q27: =Table1[[#This Row],[2023 U.S. Sales ($000)]]/SUMIF($E:$E, E27, $P:$P) -> 0.12493626 | R27: =(Table1[[#This Row],[2023 Market share (%)]]-Table1[[#This Row],[2022 Market share (%)]])*10000 -> 3.4277651 | S27: 0.031905689 | T27: 3220 | U27: =P27/T27 -> 1185.2174 | V27: 0.012578616 | W27: =_xlfn.RRI(4,AM27,P27) -> 0.083695471 | X27: =(Table1[[#This Row],[2023 Market share (%)]]-Table1[[#This Row],[2019 Market share (%)]])*10000 -> 177.20295 | Y27: =_xlfn.RRI(4,AP27,U27) -> 0.077072247 | Z27: =_xlfn.RRI(4,AO27,T27) -> 0.0061492846 | AA27: 3698400 | AB27: =Table1[[#This Row],[2022 U.S. Sales ($000)]]/SUMIF($E:$E, E27, $AA:$AA) -> 0.12459348 | AC27: 3180 | AD27: =AA27/AC27 -> 1163.0189 | AE27: 3614300 | AF27: =Table1[[#This Row],[2021 U.S. Sales ($000)]]/SUMIF($E:$E, E27, $AE:$AE) -> 0.12433708 | AG27: 3164 | AH27: =AE27/AG27 -> 1142.3198 | AI27: 3210800 | AJ27: =Table1[[#This Row],[2020 U.S. Sales ($000)]]/SUMIF($E:$E, E27, $AI:$AI) -> 0.11862451 | AK27: 3134 | AL27: =AI27/AK27 -> 1024.5054 | AM27: 2767100 | AN27: =Table1[[#This Row],[2019 U.S. Sales ($000)]]/SUMIF($E:$E, E27, $AM:$AM) -> 0.10721596 | AO27: 3142 | AP27: =AM27/AO27 -> 880.68109
A28: Whataburger | B28: 853 | C28: LSR | D28: QSR | E28: Burger | F28: 27 | H28: =Table1[[#This Row],[2024 U.S. Sales ($000)]]/SUMIF($E:$E, E28, $G:$G) -> #DIV/0! | I28: =VLOOKUP(Table1[[#This Row],[Chain Name]],[1]Sheet1!A$3:G$26,7,0) -> #N/A | J28: =Table1[[#This Row],[2024 U.S. Sales ($000)]]/Table1[[#This Row],[2024 U.S. Units]] -> #N/A | K28: =Table1[[#This Row],[2024 U.S. Units]]/Table1[[#This Row],[2023 U.S. Units]]-1 -> #N/A | L28: =_xlfn.RRI(5,Table1[[#This Row],[2019 U.S. Sales ($000)]],Table1[[#This Row],[2024 U.S. Sales ($000)]]) -> -1 | M28: =(Table1[[#This Row],[2024 Market share (%)]]-Table1[[#This Row],[2019 Market share (%)]])*10000 -> #DIV/0! | P28: 3769100 | Q28: =Table1[[#This Row],[2023 U.S. Sales ($000)]]/SUMIF($E:$E, E28, $P:$P) -> 0.034426331 | R28: =(Table1[[#This Row],[2023 Market share (%)]]-Table1[[#This Row],[2022 Market share (%)]])*10000 -> 17.349367 | S28: 0.12843927 | T28: 997 | U28: =P28/T28 -> 3780.4413 | V28: 0.077837838 | W28: =_xlfn.RRI(4,AM28,P28) -> 0.10195821 | X28: =(Table1[[#This Row],[2023 Market share (%)]]-Table1[[#This Row],[2019 Market share (%)]])*10000 -> 48.789607 | Y28: =_xlfn.RRI(4,AP28,U28) -> 0.052593923 | Z28: =_xlfn.RRI(4,AO28,T28) -> 0.04689775 | AA28: 3340100 | AB28: =Table1[[#This Row],[2022 U.S. Sales ($000)]]/SUMIF($E:$E, E28, $AA:$AA) -> 0.032691394 | AC28: 925 | AD28: =AA28/AC28 -> 3610.9189 | AE28: 3089500 | AF28: =Table1[[#This Row],[2021 U.S. Sales ($000)]]/SUMIF($E:$E, E28, $AE:$AE) -> 0.031754546 | AG28: 873 | AH28: =AE28/AG28 -> 3538.9462 | AI28: 2698300 | AJ28: =Table1[[#This Row],[2020 U.S. Sales ($000)]]/SUMIF($E:$E, E28, $AI:$AI) -> 0.030878878 | AK28: 844 | AL28: =AI28/AK28 -> 3197.0379 | AM28: 2556096 | AN28: =Table1[[#This Row],[2019 U.S. Sales ($000)]]/SUMIF($E:$E, E28, $AM:$AM) -> 0.02954737 | AO28: 830 | AP28: =AM28/AO28 -> 3079.6337
A29: Raising Cane's | B29: 2440 | C29: LSR | D29: FC | E29: Chicken | F29: 28 | H29: =Table1[[#This Row],[2024 U.S. Sales ($000)]]/SUMIF($E:$E, E29, $G:$G) -> #DIV/0! | I29: =VLOOKUP(Table1[[#This Row],[Chain Name]],[1]Sheet1!A$3:G$26,7,0) -> #N/A | J29: =Table1[[#This Row],[2024 U.S. Sales ($000)]]/Table1[[#This Row],[2024 U.S. Units]] -> #N/A | K29: =Table1[[#This Row],[2024 U.S. Units]]/Table1[[#This Row],[2023 U.S. Units]]-1 -> #N/A | L29: =_xlfn.RRI(5,Table1[[#This Row],[2019 U.S. Sales ($000)]],Table1[[#This Row],[2024 U.S. Sales ($000)]]) -> -1 | M29: =(Table1[[#This Row],[2024 Market share (%)]]-Table1[[#This Row],[2019 Market share (%)]])*10000 -> #DIV/0! | P29: 3758000 | Q29: =Table1[[#This Row],[2023 U.S. Sales ($000)]]/SUMIF($E:$E, E29, $P:$P) -> 0.07672094 | R29: =(Table1[[#This Row],[2023 Market share (%)]]-Table1[[#This Row],[2022 Market share (%)]])*10000 -> 52.592797 | S29: 0.20525978 | T29: 727 | U29: =P29/T29 -> 5169.1884 | V29: 0.125387 | W29: =_xlfn.RRI(4,AM29,P29) -> 0.26529992 | X29: =(Table1[[#This Row],[2023 Market share (%)]]-Table1[[#This Row],[2019 Market share (%)]])*10000 -> 289.62576 | Y29: =_xlfn.RRI(4,AP29,U29) -> 0.12664976 | Z29: =_xlfn.RRI(4,AO29,T29) -> 0.12306412 | AA29: 3118000 | AB29: =Table1[[#This Row],[2022 U.S. Sales ($000)]]/SUMIF($E:$E, E29, $AA:$AA) -> 0.07146166 | AC29: 646 | AD29: =AA29/AC29 -> 4826.6254 | AE29: 2377000 | AF29: =Table1[[#This Row],[2021 U.S. Sales ($000)]]/SUMIF($E:$E, E29, $AE:$AE) -> 0.060460589 | AG29: 567 | AH29: =AE29/AG29 -> 4192.2399 | AI29: 1722500 | AJ29: =Table1[[#This Row],[2020 U.S. Sales ($000)]]/SUMIF($E:$E, E29, $AI:$AI) -> 0.050932424 | AK29: 509 | AL29: =AI29/AK29 -> 3384.0864 | AM29: 1466165 | AN29: =Table1[[#This Row],[2019 U.S. Sales ($000)]]/SUMIF($E:$E, E29, $AM:$AM) -> 0.047758364 | AO29: 457 | AP29: =AM29/AO29 -> 3208.2385
A30: IHOP | B30: 818 | C30: FSR | D30: MSR | E30: Family Style | F30: 29 | H30: =Table1[[#This Row],[2024 U.S. Sales ($000)]]/SUMIF($E:$E, E30, $G:$G) -> #DIV/0! | I30: =VLOOKUP(Table1[[#This Row],[Chain Name]],[1]Sheet1!A$3:G$26,7,0) -> #N/A | J30: =Table1[[#This Row],[2024 U.S. Sales ($000)]]/Table1[[#This Row],[2024 U.S. Units]] -> #N/A | K30: =Table1[[#This Row],[2024 U.S. Units]]/Table1[[#This Row],[2023 U.S. Units]]-1 -> #N/A | L30: =_xlfn.RRI(5,Table1[[#This Row],[2019 U.S. Sales ($000)]],Table1[[#This Row],[2024 U.S. Sales ($000)]]) -> -1 | M30: =(Table1[[#This Row],[2024 Market share (%)]]-Table1[[#This Row],[2019 Market share (%)]])*10000 -> #DIV/0! | P30: 3398800 | Q30: =Table1[[#This Row],[2023 U.S. Sales ($000)]]/SUMIF($E:$E, E30, $P:$P) -> 0.19421331 | R30: =(Table1[[#This Row],[2023 Market share (%)]]-Table1[[#This Row],[2022 Market share (%)]])*10000 -> -6.3598498 | S30: 0.056118327 | T30: 1696 | U30: =P30/T30 -> 2004.0094 | V30: 0.017396521 | W30: =_xlfn.RRI(4,AM30,P30) -> 0.0097280606 | X30: =(Table1[[#This Row],[2023 Market share (%)]]-Table1[[#This Row],[2019 Market share (%)]])*10000 -> 12.470771 | Z30: =_xlfn.RRI(4,AO30,T30) -> -0.0020530978 | AA30: 3218200 | AB30: =Table1[[#This Row],[2022 U.S. Sales ($000)]]/SUMIF($E:$E, E30, $AA:$AA) -> 0.1948493 | AC30: 1667 | AD30: =AA30/AC30 -> 1930.5339 | AE30: 2997000 | AF30: =Table1[[#This Row],[2021 U.S. Sales ($000)]]/SUMIF($E:$E, E30, $AE:$AE) -> 0.1985086 | AG30: 1657 | AH30: =AE30/AG30 -> 1808.6904 | AI30: 2141000 | AJ30: =Table1[[#This Row],[2020 U.S. Sales ($000)]]/SUMIF($E:$E, E30, $AI:$AI) -> 0.20062011 | AK30: 1670 | AL30: =AI30/AK30 -> 1282.0359 | AM30: 3269700 | AN30: =Table1[[#This Row],[2019 U.S. Sales ($000)]]/SUMIF($E:$E, E30, $AM:$AM) -> 0.19296624 | AO30: 1710 | AP30: =AM30/AO30 -> 1912.1053
A31: Jersey Mike's Subs | B31: 2499 | C31: LSR | D31: FC | E31: Sandwich | F31: 30 | H31: =Table1[[#This Row],[2024 U.S. Sales ($000)]]/SUMIF($E:$E, E31, $G:$G) -> #DIV/0! | I31: =VLOOKUP(Table1[[#This Row],[Chain Name]],[1]Sheet1!A$3:G$26,7,0) -> #N/A | J31: =Table1[[#This Row],[2024 U.S. Sales ($000)]]/Table1[[#This Row],[2024 U.S. Units]] -> #N/A | K31: =Table1[[#This Row],[2024 U.S. Units]]/Table1[[#This Row],[2023 U.S. Units]]-1 -> #N/A | L31: =_xlfn.RRI(5,Table1[[#This Row],[2019 U.S. Sales ($000)]],Table1[[#This Row],[2024 U.S. Sales ($000)]]) -> -1 | M31: =(Table1[[#This Row],[2024 Market share (%)]]-Table1[[#This Row],[2019 Market share (%)]])*10000 -> #DIV/0! | P31: 3342000 | Q31: =Table1[[#This Row],[2023 U.S. Sales ($000)]]/SUMIF($E:$E, E31, $P:$P) -> 0.08848074 | R31: =(Table1[[#This Row],[2023 Market share (%)]]-Table1[[#This Row],[2022 Market share (%)]])*10000 -> 136.36814 | S31: 0.24794623 | T31: 2684 | U31: =P31/T31 -> 1245.1565 | V31: 0.119733 | W31: =_xlfn.RRI(4,AM31,P31) -> 0.25809273 | X31: =(Table1[[#This Row],[2023 Market share (%)]]-Table1[[#This Row],[2019 Market share (%)]])*10000 -> 476.41811 | Y31: =_xlfn.RRI(4,AP31,U31) -> 0.11653049 | Z31: =_xlfn.RRI(4,AO31,T31) -> 0.12678762 | AA31: 2678000 | AB31: =Table1[[#This Row],[2022 U.S. Sales ($000)]]/SUMIF($E:$E, E31, $AA:$AA) -> 0.074843925 | AC31: 2397 | AD31: =AA31/AC31 -> 1117.2299 | AE31: 2203000 | AF31: =Table1[[#This Row],[2021 U.S. Sales ($000)]]/SUMIF($E:$E, E31, $AE:$AE) -> 0.066399113 | AG31: 2100 | AH31: =AE31/AG31 -> 1049.0476 | AI31: 1595000 | AJ31: =Table1[[#This Row],[2020 U.S. Sales ($000)]]/SUMIF($E:$E, E31, $AI:$AI) -> 0.056005283 | AK31: 1854 | AL31: =AI31/AK31 -> 860.30205 | AM31: 1334000 | AN31: =Table1[[#This Row],[2019 U.S. Sales ($000)]]/SUMIF($E:$E, E31, $AM:$AM) -> 0.040838928 | AO31: 1665 | AP31: =AM31/AO31 -> 801.2012
A32: Culver's | B32: 1607 | C32: LSR | D32: QSR | E32: Burger | F32: 31 | H32: =Table1[[#This Row],[2024 U.S. Sales ($000)]]/SUMIF($E:$E, E32, $G:$G) -> #DIV/0! | I32: =VLOOKUP(Table1[[#This Row],[Chain Name]],[1]Sheet1!A$3:G$26,7,0) -> #N/A | J32: =Table1[[#This Row],[2024 U.S. Sales ($000)]]/Table1[[#This Row],[2024 U.S. Units]] -> #N/A | K32: =Table1[[#This Row],[2024 U.S. Units]]/Table1[[#This Row],[2023 U.S. Units]]-1 -> #N/A | L32: =_xlfn.RRI(5,Table1[[#This Row],[2019 U.S. Sales ($000)]],Table1[[#This Row],[2024 U.S. Sales ($000)]]) -> -1 | M32: =(Table1[[#This Row],[2024 Market share (%)]]-Table1[[#This Row],[2019 Market share (%)]])*10000 -> #DIV/0! | P32: 3310469 | Q32: =Table1[[#This Row],[2023 U.S. Sales ($000)]]/SUMIF($E:$E, E32, $P:$P) -> 0.030237272 | R32: =(Table1[[#This Row],[2023 Market share (%)]]-Table1[[#This Row],[2022 Market share (%)]])*10000 -> 15.082594 | S32: 0.12782781 | T32: 945 | U32: =P32/T32 -> 3503.1418 | V32: 0.058230683 | W32: =_xlfn.RRI(4,AM32,P32) -> 0.16529111 | X32: =(Table1[[#This Row],[2023 Market share (%)]]-Table1[[#This Row],[2019 Market share (%)]])*10000 -> 94.83671 | Y32: =_xlfn.RRI(4,AP32,U32) -> 0.093211654 | Z32: =_xlfn.RRI(4,AO32,T32) -> 0.065933673 | AA32: 2935261 | AB32: =Table1[[#This Row],[2022 U.S. Sales ($000)]]/SUMIF($E:$E, E32, $AA:$AA) -> 0.028729012 | AC32: 893 | AD32: =AA32/AC32 -> 3286.9664 | AE32: 2489100 | AF32: =Table1[[#This Row],[2021 U.S. Sales ($000)]]/SUMIF($E:$E, E32, $AE:$AE) -> 0.025583506 | AG32: 837 | AH32: =AE32/AG32 -> 2973.8351 | AI32: 1985820 | AJ32: =Table1[[#This Row],[2020 U.S. Sales ($000)]]/SUMIF($E:$E, E32, $AI:$AI) -> 0.022725381 | AK32: 782 | AL32: =AI32/AK32 -> 2539.4118 | AM32: 1795361 | AN32: =Table1[[#This Row],[2019 U.S. Sales ($000)]]/SUMIF($E:$E, E32, $AM:$AM) -> 0.020753601 | AO32: 732 | AP32: =AM32/AO32 -> 2452.679
A33: Wingstop | B33: 2409 | C33: LSR | D33: FC | E33: Chicken | F33: 32 | H33: =Table1[[#This Row],[2024 U.S. Sales ($000)]]/SUMIF($E:$E, E33, $G:$G) -> #DIV/0! | I33: =VLOOKUP(Table1[[#This Row],[Chain Name]],[1]Sheet1!A$3:G$26,7,0) -> #N/A | J33: =Table1[[#This Row],[2024 U.S. Sales ($000)]]/Table1[[#This Row],[2024 U.S. Units]] -> #N/A | K33: =Table1[[#This Row],[2024 U.S. Units]]/Table1[[#This Row],[2023 U.S. Units]]-1 -> #N/A | L33: =_xlfn.RRI(5,Table1[[#This Row],[2019 U.S. Sales ($000)]],Table1[[#This Row],[2024 U.S. Sales ($000)]]) -> -1 | M33: =(Table1[[#This Row],[2024 Market share (%)]]-Table1[[#This Row],[2019 Market share (%)]])*10000 -> #DIV/0! | P33: 3210800 | Q33: =Table1[[#This Row],[2023 U.S. Sales ($000)]]/SUMIF($E:$E, E33, $P:$P) -> 0.065549652 | R33: =(Table1[[#This Row],[2023 Market share (%)]]-Table1[[#This Row],[2022 Market share (%)]])*10000 -> 75.873244 | S33: 0.26959272 | T33: 1926 | U33: =P33/T33 -> 1667.082 | V33: 0.11911679 | W33: =_xlfn.RRI(4,AM33,P33) -> 0.23569686 | X33: =(Table1[[#This Row],[2023 Market share (%)]]-Table1[[#This Row],[2019 Market share (%)]])*10000 -> 206.92462 | Y33: =_xlfn.RRI(4,AP33,U33) -> 0.10487307 | Z33: =_xlfn.RRI(4,AO33,T33) -> 0.11840618 | AA33: 2529000 | AB33: =Table1[[#This Row],[2022 U.S. Sales ($000)]]/SUMIF($E:$E, E33, $AA:$AA) -> 0.057962328 | AC33: 1721 | AD33: =AA33/AC33 -> 1469.4945 | AE33: 2165000 | AF33: =Table1[[#This Row],[2021 U.S. Sales ($000)]]/SUMIF($E:$E, E33, $AE:$AE) -> 0.055068226 | AG33: 1534 | AH33: =AE33/AG33 -> 1411.3429 | AI33: 1804000 | AJ33: =Table1[[#This Row],[2020 U.S. Sales ($000)]]/SUMIF($E:$E, E33, $AI:$AI) -> 0.053342289 | AK33: 1359 | AL33: =AI33/AK33 -> 1327.4467 | AM33: 1377100 | AN33: =Table1[[#This Row],[2019 U.S. Sales ($000)]]/SUMIF($E:$E, E33, $AM:$AM) -> 0.04485719 | AO33: 1231 | AP33: =AM33/AO33 -> 1118.684
